Workbook

Sheet Sales Pipeline
B2: Hercas — levantamiento de requerimientos
B3: Backend, frontend, integraciones y servicios. Corte documental y de código: 18/09/2026.
B5: REQUERIMIENTOS | G5: COMPLEJIDAD ALTA O MUY ALTA | L5: DECISIONES PENDIENTES
B6: =COUNTA(Requerimientos!$A$7:$A$1000) | G6: =COUNTIFS(Requerimientos!$I$7:$I$1000,"Alta")+COUNTIFS(Requerimientos!$I$7:$I$1000,"Muy alta") | L6: =COUNTIFS(Decisiones!$I$7:$I$1000,"Pendiente")
B9: BACKEND | G9: FRONTEND | L9: INTEGRACIONES Y SERVICIOS
B10: =COUNTIFS(Requerimientos!$B$7:$B$1000,"Backend") | G10: =COUNTIFS(Requerimientos!$B$7:$B$1000,"Frontend") | L10: =COUNTIFS(Requerimientos!$B$7:$B$1000,"Integraciones")+COUNTIFS(Requerimientos!$B$7:$B$1000,"Servicios")
B13: Estado observado por área
B15: Área | E15: Total | F15: Código local | H15: Base BD | J15: Piloto | K15: Parcial | L15: Planificado | N15: Por definir
B16: Backend | E16: =COUNTIFS(Requerimientos!$B$7:$B$1000,B16) | F16: =COUNTIFS(Requerimientos!$B$7:$B$1000,B16,Requerimientos!$G$7:$G$1000,"Código local") | H16: =COUNTIFS(Requerimientos!$B$7:$B$1000,B16,Requerimientos!$G$7:$G$1000,"Base BD documentada") | J16: =COUNTIFS(Requerimientos!$B$7:$B$1000,B16,Requerimientos!$G$7:$G$1000,"Piloto") | K16: =COUNTIFS(Requerimientos!$B$7:$B$1000,B16,Requerimientos!$G$7:$G$1000,"Parcial") | L16: =COUNTIFS(Requerimientos!$B$7:$B$1000,B16,Requerimientos!$G$7:$G$1000,"Planificado") | N16: =COUNTIFS(Requerimientos!$B$7:$B$1000,B16,Requerimientos!$G$7:$G$1000,"Por definir")
B17: Frontend | E17: =COUNTIFS(Requerimientos!$B$7:$B$1000,B17) | F17: =COUNTIFS(Requerimientos!$B$7:$B$1000,B17,Requerimientos!$G$7:$G$1000,"Código local") | H17: =COUNTIFS(Requerimientos!$B$7:$B$1000,B17,Requerimientos!$G$7:$G$1000,"Base BD documentada") | J17: =COUNTIFS(Requerimientos!$B$7:$B$1000,B17,Requerimientos!$G$7:$G$1000,"Piloto") | K17: =COUNTIFS(Requerimientos!$B$7:$B$1000,B17,Requerimientos!$G$7:$G$1000,"Parcial") | L17: =COUNTIFS(Requerimientos!$B$7:$B$1000,B17,Requerimientos!$G$7:$G$1000,"Planificado") | N17: =COUNTIFS(Requerimientos!$B$7:$B$1000,B17,Requerimientos!$G$7:$G$1000,"Por definir")
B18: Integraciones | E18: =COUNTIFS(Requerimientos!$B$7:$B$1000,B18) | F18: =COUNTIFS(Requerimientos!$B$7:$B$1000,B18,Requerimientos!$G$7:$G$1000,"Código local") | H18: =COUNTIFS(Requerimientos!$B$7:$B$1000,B18,Requerimientos!$G$7:$G$1000,"Base BD documentada") | J18: =COUNTIFS(Requerimientos!$B$7:$B$1000,B18,Requerimientos!$G$7:$G$1000,"Piloto") | K18: =COUNTIFS(Requerimientos!$B$7:$B$1000,B18,Requerimientos!$G$7:$G$1000,"Parcial") | L18: =COUNTIFS(Requerimientos!$B$7:$B$1000,B18,Requerimientos!$G$7:$G$1000,"Planificado") | N18: =COUNTIFS(Requerimientos!$B$7:$B$1000,B18,Requerimientos!$G$7:$G$1000,"Por definir")
B19: Servicios | E19: =COUNTIFS(Requerimientos!$B$7:$B$1000,B19) | F19: =COUNTIFS(Requerimientos!$B$7:$B$1000,B19,Requerimientos!$G$7:$G$1000,"Código local") | H19: =COUNTIFS(Requerimientos!$B$7:$B$1000,B19,Requerimientos!$G$7:$G$1000,"Base BD documentada") | J19: =COUNTIFS(Requerimientos!$B$7:$B$1000,B19,Requerimientos!$G$7:$G$1000,"Piloto") | K19: =COUNTIFS(Requerimientos!$B$7:$B$1000,B19,Requerimientos!$G$7:$G$1000,"Parcial") | L19: =COUNTIFS(Requerimientos!$B$7:$B$1000,B19,Requerimientos!$G$7:$G$1000,"Planificado") | N19: =COUNTIFS(Requerimientos!$B$7:$B$1000,B19,Requerimientos!$G$7:$G$1000,"Por definir")
F20: =COUNTIFS(Requerimientos!$B$7:$B$1000,B20,Requerimientos!$G$7:$G$1000,"Código local") | J20: =COUNTIFS(Requerimientos!$B$7:$B$1000,B20,Requerimientos!$G$7:$G$1000,"Piloto") | O20: =IF(B20="","",E20*F20)
F21: =COUNTIFS(Requerimientos!$B$7:$B$1000,B21,Requerimientos!$G$7:$G$1000,"Código local") | J21: =COUNTIFS(Requerimientos!$B$7:$B$1000,B21,Requerimientos!$G$7:$G$1000,"Piloto") | O21: =IF(B21="","",E21*F21)
B22: Los conteos describen evidencia disponible. No equivalen a funciones aceptadas ni a un porcentaje de avance.
B24: Requerimientos: 83 registros filtrables con alcance, historia de usuario, complejidad, prioridad, dependencias y aceptación.
B26: Decisiones: 20 asuntos con campos para registrar acuerdo, responsable y fecha. Guía y fuentes: definiciones y evidencia.
B28: Prioridades y complejidad son propuestas para validar. No se estimaron horas, costos ni fechas de entrega.
B30: Atención: inventario del sitio y fuentes comerciales usan cortes distintos. Conciliar antes de publicar disponibilidad.
B32: Avance localizado: API, base de identidad/comercial, web pública y piloto cotizador. Falta verificar integración completa.
B34: La revisión fue local y documental. No se modificó código del proyecto ni se operaron servicios remotos.
F36: =COUNTIFS(Requerimientos!$B$7:$B$1000,B36,Requerimientos!$G$7:$G$1000,"Código local") | J36: =COUNTIFS(Requerimientos!$B$7:$B$1000,B36,Requerimientos!$G$7:$G$1000,"Piloto") | O36: =IF(B36="","",E36*F36)
F37: =COUNTIFS(Requerimientos!$B$7:$B$1000,B37,Requerimientos!$G$7:$G$1000,"Código local") | J37: =COUNTIFS(Requerimientos!$B$7:$B$1000,B37,Requerimientos!$G$7:$G$1000,"Piloto") | O37: =IF(B37="","",E37*F37)
B38: Plan de ejecución añadido: abrir Plan a dos, Asignación 83 y Cierre de etapas. Tú: Supabase + frontend. Anderson: API + integraciones externas.

Sheet Requerimientos
A2: Hercas — requerimientos e historias de usuario
A4: Corte 18/09/2026. Filtrar por área o módulo. Complejidad, prioridad e historias son propuestas de análisis pendientes de validación.
A6: ID | B6: Área | C6: Módulo | D6: Requerimiento | E6: Alcance y límite | F6: Origen del alcance | G6: Estado observado | H6: Brecha / siguiente paso | I6: Complejidad propuesta | J6: Motivo de complejidad | K6: Prioridad propuesta | L6: Dependencias / decisiones | M6: Historia de usuario propuesta | N6: Criterios de aceptación propuestos | O6: Fuentes | P6: Validación del negocio
A7: BE-001 | B7: Backend | C7: Plataforma | D7: API modular común | E7: FastAPI con prefijos por módulo, configuración, cliente HTTP, errores y healthcheck. | F7: Existente observado | G7: Código local | H7: Verificar despliegue y contrato consumido por cada frontend. | I7: Media | J7: Infraestructura compartida y compatibilidad de contratos. | K7: P0 | L7: — | M7: Como equipo de desarrollo, quiero usar una API común para integrar los módulos con contratos consistentes. | N7: Healthcheck no depende de Odoo. Errores externos no revelan cuerpos ni secretos. Módulos futuros no se anuncian como rutas activas. | O7: S01, S02 | P7: Pendiente
A8: BE-002 | B8: Backend | C8: Usuarios | D8: Sesión y autorización | E8: Validar JWT, perfil activo y roles no revocados. Propagar JWT para RLS. | F8: Existente observado | G8: Código local | H8: Probar Auth real, revocación y sesión completa desde el sitio. | I8: Alta | J8: Identidad y permisos afectan todas las operaciones. | K8: P0 | L8: INT-002 | M8: Como usuario autorizado, quiero acceder con mi sesión y permisos vigentes para trabajar únicamente con información permitida. | N8: Token inválido devuelve 401. Perfil inactivo o rol no autorizado no opera. Un usuario sin rol comercial puede tener sesión sin acceder al cotizador. | O8: S03, S05 | P8: Pendiente
A9: BE-003 | B9: Backend | C9: Usuarios | D9: Empresas cliente y aislamiento | E9: Una operadora Hercas y múltiples personas por empresa cliente, con membresía verificada. | F9: Confirmado documental | G9: Base BD documentada | H9: Validar acceso remoto con dos empresas y conectar portal. | I9: Alta | J9: Aislamiento por fila, membresías y referencias ERP. | K9: P0 | L9: BE-002, INT-002 | M9: Como cliente, quiero consultar únicamente mi empresa para proteger mis documentos y reportes. | N9: El alcance se obtiene en servidor. Cambiar un ID no revela otra empresa. Revocar membresía retira acceso. | O9: S03, S05 | P9: Pendiente
A10: BE-004 | B10: Backend | C10: Usuarios | D10: Aceptación de invitaciones | E10: Aceptar autorización vigente vinculada al usuario Auth verificado. | F10: Existente observado | G10: Código local | H10: Completar envío Auth y pantalla de aceptación. | I10: Alta | J10: Transacción, identidad verificada y reintentos. | K10: P0 | L10: BE-002, INT-003 | M10: Como persona invitada, quiero activar el acceso autorizado para ingresar con el rol y empresa correctos. | N10: Invitación vencida o revocada falla. Repetir aceptación no duplica roles ni restaura permisos revocados. No permite convertir cliente en empleado. | O10: S03, S05 | P10: Pendiente
A11: BE-005 | B11: Backend | C11: Usuarios | D11: Administración de accesos | E11: RPC para crear/revocar invitación, cambiar roles internos y activar/desactivar empleados. | F11: Existente observado | G11: Parcial: migración remota aplicada y validada | H11: 25/09: RPC admin_update_role_permissions aplicado en Supabase; anónimo bloqueado, autenticado habilitado y trigger de auditoría verificado. UI permite editar módulos por rol. Falta validar recorrido real completo de correo/invitación. | I11: Alta | J11: Gestión privilegiada y protección del último administrador. | K11: P0 | L11: BE-002, BE-004 | M11: Como administrador, quiero gestionar accesos y roles para controlar altas y bajas sin modificar tablas manualmente. | N11: Solo users.manage opera. Rol inválido se rechaza. El último administrador permanece activo. Un envío de correo fallido no se reporta como invitación entregada. | O11: S06 | P11: Pendiente: validar envío real y aceptar invitación; evidencia SQL y prueba local de autorización disponibles.
A12: BE-006 | B12: Backend | C12: Cotizador | D12: Consultas de catálogo, activos y clientes | E12: Lecturas paginadas, campos explícitos y solo registros activos/visibles autorizados. | F12: Existente observado | G12: Código local | H12: Cargar catálogo aprobado y conciliar IDs. | I12: Media | J12: Contratos de tres recursos con RLS. | K12: P0 | L12: BE-002, INT-004 | M12: Como asesor comercial, quiero consultar productos y clientes válidos para preparar cotizaciones con referencias coherentes. | N12: Límite entre 1 y 100. Inventario no expone source_metadata ni soportes. Productos ocultos no se ofrecen. | O12: S04 | P12: Pendiente
A13: BE-007 | B13: Backend | C13: Cotizador | D13: Simulación aritmética | E13: Alquiler, adicionales, descuento, impuesto y total con Decimal y redondeo definido. | F13: Existente observado | G13: Código local | H13: La simulación no guarda ni valida tarifas oficiales. | I13: Media | J13: Exactitud monetaria y compatibilidad con piloto. | K13: P0 | L13: BE-002 | M13: Como asesor comercial, quiero simular el importe de una propuesta para revisar sus componentes antes de emitir. | N13: Caso documentado produce 4.926.600 COP. Rechaza valores no finitos y fuera de rango. El resultado no constituye documento oficial. | O13: S01, S04, S07 | P13: Pendiente
A14: BE-008 | B14: Backend | C14: Cotizador | D14: Resolución de precios y acuerdos | E14: Precedencia: cliente/producto, cliente/línea, cliente/portafolio, tipo de cliente y tarifa normal. | F14: Existente observado | G14: Código local | H14: Es motor de simulación. Integrar reglas autorizadas con persistencia oficial. | I14: Alta | J14: Precedencia, vigencias y acuerdos específicos. | K14: P0 | L14: BE-009, BE-010 | M14: Como administrador de precios, quiero resolver la tarifa aplicable para evitar acuerdos contradictorios. | N14: Borradores no resuelven precio cotizable. Vigencia inclusiva. Publicación requiere autor y fecha. La revisión mensual no invalida por sí sola la última tarifa publicada. | O14: S07, S09 | P14: Pendiente
A15: BE-009 | B15: Backend | C15: Cotizador | D15: Versiones oficiales de tarifas | E15: Importe, COP, unidad comercial, impuesto explícito, vigencia y publicación inmutable. | F15: Confirmado documental | G15: Base BD documentada | H15: Faltan API y panel completos para editar/publicar sin operador SQL. Confirmar monedas y reglas de descuento. | I15: Alta | J15: Integridad temporal y protección del precio oficial. | K15: P0 | L15: BE-006, D-003 | M15: Como administrador de precios, quiero publicar tarifas por producto para dar al equipo una referencia vigente. | N15: No se superponen versiones publicadas de un producto. Una versión publicada se retira, no cambia su importe. Disponibilidad no concede permiso de precios. | O15: S08 | P15: Pendiente
A16: BE-010 | B16: Backend | C16: Cotizador | D16: Gestión de tarifas por API | E16: Crear borrador, validar, publicar/retirar, historial y control de cambios concurrentes. | F16: Derivado del alcance | G16: Planificado | H16: Definir endpoints y revisión esperada. No usar como autoridad el tarifario enviado por navegador. | I16: Alta | J16: Transiciones, autorización y concurrencia. | K16: P0 | L16: BE-009, D-003 | M16: Como administrador de precios, quiero administrar tarifas desde el panel para evitar intervención SQL diaria. | N16: Un usuario sin permiso no publica. Dos ediciones incompatibles devuelven conflicto. Una publicación registra actor, fecha y versión. | O16: S02, S08 | P16: Pendiente
A17: BE-011 | B17: Backend | C17: Cotizador | D17: Cotización persistida e instantáneas | E17: Cabecera, líneas, importes e instantáneas de cliente, requerimientos y precio. | F17: Confirmado documental | G17: Base BD documentada | H17: Escritura actual por operador SQL. Falta flujo de guardado API y acuerdos/descuentos completos. | I17: Alta | J17: Documento comercial transaccional e inmutable. | K17: P0 | L17: BE-009 | M17: Como asesor comercial, quiero guardar la versión exacta de una propuesta para recuperar sus condiciones sin cambios posteriores. | N17: La BD resuelve el precio oficial. Emisión exige líneas y vigencia. Documento emitido no cambia con una tarifa nueva. No asumir equivalencia del redondeo SQL y piloto. | O17: S08 | P17: Pendiente
... A89: SER-014 | B89: Servicios | C89: Gobierno de datos | D89: Autoridad y retención de datos | E89: Definir dueño de cada dato, frescura, consentimiento, acceso y ciclo de conservación. | F89: Derivado del alcance | G89: Por definir | H89: Cerrar reglas de identidad, precios, inventario, CRM, conversaciones y soportes. | I89: Alta | J89: Varios sistemas con responsabilidades distintas. | K89: P0 | L89: D-003, D-005, D-014, D-020 | M89: Como responsable del proyecto, quiero acordar la autoridad y conservación de datos para evitar fuentes contradictorias y retención indefinida. | N89: Documento de decisiones identifica sistema maestro y responsable por recurso. Cambios no crean autoridades paralelas para precio o capacidad. | O89: S02, S13 | P89: Pendiente

Sheet Decisiones
A2: Decisiones para cerrar el alcance
A4: Responsables funcionales sugeridos. Las decisiones y fechas en amarillo se completan durante el levantamiento con Hercas.
A6: ID | B6: Tema | C6: Decisión requerida | D6: Situación / límite actual | E6: Áreas afectadas | F6: Responsable sugerido | G6: Prioridad propuesta | H6: Fuentes | I6: Estado | J6: Decisión acordada | K6: Responsable asignado | L6: Fecha de acuerdo | M6: Coordina la decisión | N6: Resolver antes de etapa | O6: Acción anticipada | P6: Alcance del acuerdo | Q6: Verificación del acuerdo
A7: D-001 | B7: Inventario vigente | C7: Conciliar 140 del sitio, 93 ubicaciones del maestro, 113 códigos conciliados y resumen 83 frente a 82 identificados en corte 06–12/09. | D7: No publicar cantidad ni disponibilidad operativa sin corte e IDs aprobados. | E7: Catálogo, migración y web | F7: Comercial + encargada de disponibilidad | G7: P0 | H7: S10, S11, S15 | I7: Pendiente | M7: Tú | N7: 3 | O7: Recoger fuente/criterio desde etapa 0 y confirmar con el dueño de negocio. | P7: Registrar alternativa elegida y límites. El coordinador no reemplaza al aprobador del negocio. | Q7: =IF(AND(I7="Acordada",J7<>"",K7<>"",ISNUMBER(L7)),"Sí","No")
A8: D-002 | B8: Geolocalización | C8: Entregar coordenadas verificadas por activo y confirmar uso de pines orientativos. | D8: Mapa actual usa centroides y dispersión, no coordenadas del poste. | E8: Mapa y fichas | F8: Operación de inventario | G8: P1 | H8: S11 | I8: Pendiente | M8: Tú | N8: 3 | O8: Recoger fuente/criterio desde etapa 0 y confirmar con el dueño de negocio. | P8: Registrar alternativa elegida y límites. El coordinador no reemplaza al aprobador del negocio. | Q8: =IF(AND(I8="Acordada",J8<>"",K8<>"",ISNUMBER(L8)),"Sí","No")
A9: D-003 | B9: Precios y unidades | C9: Confirmar moneda, unidades, reglas de fabricación, descuentos, redondeo y responsables de aprobación. | D9: BD nueva usa COP y descuento cero. Maestro carece de precios; historia no trae moneda/unidad por línea. | E9: Tarifas y emisión | F9: Administrador de precios + comercial | G9: P0 | H9: S08, S10, S07 | I9: Pendiente | M9: Tú | N9: 0 | O9: Recoger fuente/criterio desde etapa 0 y confirmar con el dueño de negocio. | P9: Cerrar reglas comunes en etapa 0 y verificar detalles de cada módulo antes de su etapa. | Q9: =IF(AND(I9="Acordada",J9<>"",K9<>"",ISNUMBER(L9)),"Sí","No")
A10: D-004 | B10: Documento y contratación | C10: Definir evento de creación en Odoo, vigencia, aceptación, corrección y cuándo se reserva o cobra. | D10: Cotización, reserva, pago y aprobación visual son estados distintos. | E10: Cotizador, pagos y Odoo | F10: Dirección comercial + finanzas | G10: P0 | H10: S02, S08 | I10: Pendiente | M10: Tú | N10: 4 | O10: Recoger fuente/criterio desde etapa 0 y confirmar con el dueño de negocio. | P10: Registrar alternativa elegida y límites. El coordinador no reemplaza al aprobador del negocio. | Q10: =IF(AND(I10="Acordada",J10<>"",K10<>"",ISNUMBER(L10)),"Sí","No")
A11: D-005 | B11: Disponibilidad operativa | C11: Definir conciliacion ERP, expiracion de separaciones, liberacion entre comerciales, conversion a alquiler y confirmacion segura tras pago del cliente final. | D11: 30/09: website y calendario Supabase son centro de consulta de disponibilidad. Tres estados diarios: disponible, reservada y ocupada. Por autorización de Carlos se habilitaron provisionalmente las 85 vallas en hercas-platform-dev para probar /disponibilidad; las 85 siguen marcadas para revisión por Katherine, sin last_verified_at ni ocupaciones activas. Vista frontend conectada y comprobada en navegador; refresca cada 30 segundos. Antes de confirmar una contratación hay que conciliar contratos, bloqueos y fechas reales. Reservas, pagos e integración comercial quedan para etapa posterior. Evidencia: migraciones 20260930223345 y 20260930223637, docs/disponibilidad-centro-control.md. | E11: Disponibilidad y sincronización | F11: Encargada de disponibilidad + comercial | G11: P0 | H11: S02, S07, S08 | I11: Pendiente | M11: Tú | N11: 0 | O11: Priorizar consulta unica de disponibilidad por fechas y tablero simple de tres estados. Luego conectar cotizador, reserva temporal, confirmacion tras pago y liberacion segura; probar concurrencia. Definir vencimiento y conciliacion ERP. | P11: Cerrar reglas comunes en etapa 0 y verificar detalles de cada módulo antes de su etapa. | Q11: =IF(AND(I11="Acordada",J11<>"",K11<>"",ISNUMBER(L11)),"Sí","No")
A12: D-006 | B12: Pantallas digitales | C12: Inventariar sistema, dispositivos, API y capacidad vendida. Aclarar programación automática frente a compra DSP/SSP. | D12: No se presume compra programática externa ni soporte de reproducción offline específico. | E12: Pantallas y reservas | F12: Operación de pantallas + comercial | G12: P1 | H12: S02 | I12: Pendiente | M12: Anderson | N12: 10 | O12: Solicitar acceso, opciones y condiciones desde etapa 0. Resolver antes de etapa indicada. | P12: Registrar alternativa elegida y límites. El coordinador no reemplaza al aprobador del negocio. | Q12: =IF(AND(I12="Acordada",J12<>"",K12<>"",ISNUMBER(L12)),"Sí","No")
A13: D-007 | B13: Catálogo configurable | C13: Aprobar familias y referencias publicables, opciones y fórmulas por producto. | D13: 206 referencias no son 206 productos listos. Materiales y registros internos requieren tratamiento separado. | E13: Portafolio y fabricación | F13: Catálogo + producción + precios | G13: P0 | H13: S10 | I13: Pendiente | M13: Tú | N13: 3 | O13: Recoger fuente/criterio desde etapa 0 y confirmar con el dueño de negocio. | P13: Registrar alternativa elegida y límites. El coordinador no reemplaza al aprobador del negocio. | Q13: =IF(AND(I13="Acordada",J13<>"",K13<>"",ISNUMBER(L13)),"Sí","No")
A14: D-008 | B14: Renders | C14: Elegir montaje, imagen conceptual o 3D, precisión, costo, plazo, revisiones y aprobadores. | D14: No presupone proveedor ni que aprobar visual implique contratar. | E14: Renderización | F14: Diseño + comercial | G14: P1 | H14: S02 | I14: Pendiente | M14: Anderson | N14: 6 | O14: Solicitar acceso, opciones y condiciones desde etapa 0. Resolver antes de etapa indicada. | P14: Registrar alternativa elegida y límites. El coordinador no reemplaza al aprobador del negocio. | Q14: =IF(AND(I14="Acordada",J14<>"",K14<>"",ISNUMBER(L14)),"Sí","No")
A15: D-009 | B15: Reportes iniciales | C15: Elegir reporte interno y de cliente, indicadores, filtros, periodicidad y exportación. | D15: Definir denominadores y fuentes antes de diseñar tableros. | E15: Reportes | F15: Dirección + clientes piloto | G15: P1 | H15: S02 | I15: Pendiente | M15: Tú | N15: 8 | O15: Recoger fuente/criterio desde etapa 0 y confirmar con el dueño de negocio. | P15: Registrar alternativa elegida y límites. El coordinador no reemplaza al aprobador del negocio. | Q15: =IF(AND(I15="Acordada",J15<>"",K15<>"",ISNUMBER(L15)),"Sí","No")
A16: D-010 | B16: Pagos | C16: Elegir pasarela, país, monedas, parciales, reembolsos, contracargos y conciliación contable. | D16: No se han habilitado pagos reales en el alcance documentado. | E16: Checkout y Odoo | F16: Finanzas | G16: P1 | H16: S02 | I16: Pendiente | M16: Anderson | N16: 8 | O16: Solicitar acceso, opciones y condiciones desde etapa 0. Resolver antes de etapa indicada. | P16: Registrar alternativa elegida y límites. El coordinador no reemplaza al aprobador del negocio. | Q16: =IF(AND(I16="Acordada",J16<>"",K16<>"",ISNUMBER(L16)),"Sí","No")
A17: D-011 | B17: Contenido y lanzamiento | C17: Confirmar contenido a migrar, aprobadores, casos reales, textos institucionales y legales, dominio y redirecciones. | D17: Casos es placeholder. Código SEO no acredita posicionamiento ni validación productiva. | E17: CMS y web pública | F17: Marketing + gerencia | G17: P0 | H17: S02, S11 | I17: Pendiente | M17: Tú | N17: 3 | O17: Recoger fuente/criterio desde etapa 0 y confirmar con el dueño de negocio. | P17: Registrar alternativa elegida y límites. El coordinador no reemplaza al aprobador del negocio. | Q17: =IF(AND(I17="Acordada",J17<>"",K17<>"",ISNUMBER(L17)),"Sí","No")
A18: D-012 | B18: Redes sociales | C18: Elegir primera red/cuenta, titularidad, formatos, frecuencia y roles de aprobación. | D18: No se asume cobertura de todas las redes ni publicación sin revisión. | E18: Blogs y redes | F18: Marketing | G18: P1 | H18: S02 | I18: Pendiente | M18: Anderson | N18: 9 | O18: Solicitar acceso, opciones y condiciones desde etapa 0. Resolver antes de etapa indicada. | P18: Registrar alternativa elegida y límites. El coordinador no reemplaza al aprobador del negocio. | Q18: =IF(AND(I18="Acordada",J18<>"",K18<>"",ISNUMBER(L18)),"Sí","No")
... A26: D-020 | B26: Límites y conservación | C26: Acordar cuotas, tipos/tamaños de archivo, retención de conversaciones, CRM, reportes y soportes. | D26: Los límites requieren dimensionamiento. Privacidad debe reflejar los flujos reales. | E26: Seguridad y datos | F26: Responsable de datos + sistemas | G26: P0 | H26: S13 | I26: Pendiente | M26: Tú | N26: 0 | O26: Recoger fuente/criterio desde etapa 0 y confirmar con el dueño de negocio. | P26: Cerrar reglas comunes en etapa 0 y verificar detalles de cada módulo antes de su etapa. | Q26: =IF(AND(I26="Acordada",J26<>"",K26<>"",ISNUMBER(L26)),"Sí","No")

Sheet Guía y fuentes
A2: Criterios de lectura y evidencia
A5: Criterio | B5: Aplicación
A6: Cobertura | B6: Revisión de la documentación, API Python, migraciones y worktrees locales del sitio y piloto. Corte: 18/09/2026.
A7: Límite de verificación | B7: Se inspeccionaron fuentes locales. No se probó el sistema en producción, no se ejecutaron pruebas del proyecto ni se revalidó Supabase/Odoo remoto.
A8: Alcance confirmado | B8: Siete módulos: usuarios, cotizador, reportes, pagos, CMS, blogs/redes y agente. Pantallas, renders y captación CRM son ampliaciones documentadas.
A9: Origen del alcance | B9: Existente observado: encontrado en código/piloto. Confirmado documental: capacidad o decisión expresa. Derivado del alcance: descomposición propuesta para implementar/validar.
A10: Código local | B10: La función o interfaz existe en archivos revisados. No significa integrada, desplegada, probada de extremo a extremo ni aprobada por el negocio.
A11: Base BD documentada | B11: Reglas y tablas con aplicación en desarrollo reportada en documentos. La evidencia remota corresponde al corte descrito por esas fuentes.
A12: Piloto | B12: Funcionalidad experimental o con almacenamiento local/datos orientativos. No representa operación compartida de producción.
A13: Parcial | B13: Hay evidencia de una parte de la capacidad. La columna de brecha indica lo que queda por completar o verificar.
A14: Planificado / Por definir | B14: Planificado: capacidad documentada sin implementación completa localizada. Por definir: necesita decisión de negocio o proveedor antes de cerrar diseño.
A15: Complejidad Baja / Media | B15: Baja: interacción o adaptación puntual con pocas reglas. Media: varias validaciones o vistas con contratos conocidos. Estimación cualitativa, no horas.
A16: Complejidad Alta / Muy alta | B16: Alta: permisos, transacciones, reglas o integración externa relevantes. Muy alta: concurrencia/capacidad, múltiples proveedores o alta incertidumbre de datos/proceso.
... A23: Indicadores del resumen | B23: Son cantidades de requisitos por clasificación. No representan porcentaje de avance, esfuerzo completado ni aceptación productiva.
A26: Fuentes consultadas
A28: Fuente | B28: Documento / componente | C28: Localizador de evidencia | D28: Alcance de la evidencia
A29: S01 | B29: Backend y estructura | C29: README.md y app/main.py | D29: API 0.3.0, ejecución, simulación y límites. Lectura local 18/09/2026.
A30: S02 | B30: Alcance y arquitectura | C30: docs/arquitectura.md | D30: Siete módulos, ampliaciones confirmadas y propuestas técnicas. Las preguntas no todas reflejan decisiones posteriores.
A31: S03 | B31: Identidad API | C31: app/api/auth.py y app/core/auth.py | D31: Sesión, empresas, aceptación de invitación, perfil activo y roles.
A32: S04 | B32: Rutas del cotizador | C32: app/modules/cotizador/router.py | D32: Consultas y simulaciones existentes. No se localizaron endpoints de guardado/emisión.
A33: S05 | B33: Base de identidad | C33: supabase/README.md y migraciones de identidad del 17/09 | D33: Aplicación remota descrita en documento. No se revalidó el entorno remoto en este levantamiento.
A34: S06 | B34: Administración posterior | C34: 20260918143323_auth_administration.sql | D34: RPC administrativa localizada. Prevalece para existencia de código frente al README anterior. Despliegue no confirmado.
A35: S07 | B35: Migración de dominio | C35: docs/migracion.md y app/modules/cotizador/domain | D35: Reglas piloto y diferencias de persistencia. La base SQL posterior actualiza parte de las brechas de este documento.
A36: S08 | B36: Base comercial | C36: supabase/COTIZADOR.md y migración 20260917224601 | D36: Tarifas, cotizaciones, exclusión diaria y límites. Pruebas previas reportadas, no repetidas en este levantamiento.
A37: S09 | B37: Piloto del cotizador | C37: app/.worktrees/supabase-inventario-vallas/README.md y rutas src/app | D37: Piloto Next.js, 205 referencias previas, 94 puntos, tarifas y cotizaciones en localStorage. No es operación compartida.
A38: S10 | B38: Auditoría de catálogo | C38: docs/catalogo-auditoria-2026-09-17.md | D38: 206 referencias, 204 candidatas y 2 internas. 113 códigos conciliados. Datos históricos, no disponibilidad actual.
A39: S11 | B39: Sitio público local | C39: Worktree website-auth: app, components, data y next.config.ts | D39: Páginas, catálogo, mapa, SEO, rutas pendientes. Revisión estática sin acreditar despliegue ni experiencia real.
... A43: S15 | B43: Conciliación más reciente localizada | C43: outputs/catalogo-20260917/Conciliacion de 83 vallas.md | D43: Corte 06–12/09/2026. Resumen 83 frente a 82 filas identificadas como disponibles/arrendadas. Visibilidad no aplicada.

Sheet Plan a dos
A2: Hercas — dos operaciones en paralelo
A4: Tú: Supabase completo, frontend y aceptación. Anderson: FastAPI, Python, Odoo, integraciones externas y trabajadores.
A6: Etapa | B6: Entrega | C6: Operación 1 — Tú | D6: Operación 2 — Anderson | E6: Criterio para cerrar la etapa | F6: Cómo trabajar sin esperas | G6: Requisitos que cierran aquí | H6: Cantidad
A7: 0 | B7: Preparación y contratos | C7: Inspeccionar Supabase real: migraciones, Auth, RLS, Storage y datos. Consolidar decisiones, accesos a proveedores y recorrido de aceptación. | D7: Inspeccionar API y Odoo. Entregar contrato de sesión, errores, roles e IDs. Ejecutar pruebas existentes en entorno autorizado y registrar brechas. | E7: Diagnóstico y contratos versionados. Decisiones D-003/005/014/016/019/020 acordadas para habilitar sus trabajos dependientes. No se ejecutan ni se cierran requisitos funcionales en etapa 0. Proveedores futuros con responsable y fecha límite. | F7: Acordar contrato de identidad y usuario activo. Nadie cambia simultáneamente el mismo archivo o migración. | H7: =COUNTIFS('Asignación 83'!$F$7:$F$89,A7)
A8: 1 | B8: Identidad y entorno común | C8: Auth/MFA, RLS, empresas, membresías y RPC de administración. Después conectar invitación/login, panel de usuarios y navegación privada. | D8: FastAPI: sesión, aceptación, errores y autorización. Preparar entornos API, auditoría básica, perímetro, monitoreo y recuperación; tú ejecutas toda configuración Supabase. | E8: Invitar, aceptar, entrar, revocar y volver a intentar. Dos empresas aisladas. Último administrador protegido. Backend y frontend usan la misma identidad real. | F8: Primero contrato. Anderson implementa API mientras tú haces esquema/RPC; después conectas UI y Anderson prepara pruebas negativas. | G8: BE-001, BE-002, BE-003, BE-004, BE-005, INT-002, INT-003, SER-001, FE-010, FE-011, FE-012 | H8: =COUNTIFS('Asignación 83'!$F$7:$F$89,A8)
A9: 2 | B9: Archivos y trabajos comunes | C9: Configurar Storage, políticas, tipos y tamaños de archivo. Probar carga/descarga privada con dos identidades. Entregar contrato de archivo al frontend. | D9: Implementar cola/trabajador persistente y estados de trabajo. Validar contenido, límites y recuperación de tareas. Conectar referencias Storage sin administrar Supabase. | E9: Archivo privado inaccesible a otro cliente. Job sobrevive reinicio, no duplica trabajo y permite consultar fallo. Cuotas y registro de actividad comprobados. | F9: No elegir un proveedor de colas por suposición. Si se usa Supabase, su configuración y esquema los haces tú; Anderson implementa el consumidor. | G9: SER-002, SER-005, INT-015 | H9: =COUNTIFS('Asignación 83'!$F$7:$F$89,A9)
A10: 3 | B10: Catálogo y web de consulta | C10: Conciliar IDs y catálogo aprobado. Tú ejecutas importación a Supabase. Conectar portafolio, filtros, fichas y mapa con visibilidad verificada. | D10: Odoo de lectura, mapeos y sincronización. Entregar payload de importación validado y APIs de catálogo. Distinguir ERP caído de catálogo vacío. | E10: Referencias/activos/paquetes conciliados. Fotos y fichas corresponden al activo. Pines aproximados identificados. Sincronización no modifica tarifas web. | F10: Anderson prepara extracción y validadores; tú apruebas/cargas datos y conectas pantallas. No ofrecer disponibilidad actual desde fuentes históricas. | G10: BE-006, INT-001, INT-004, INT-005, INT-013, FE-002, FE-003, FE-004, FE-005 | H10: =COUNTIFS('Asignación 83'!$F$7:$F$89,A10)
A11: 4 | B11: Tarifas oficiales | C11: Versiones y restricciones SQL/RLS. Panel de revisar, editar, publicar y retirar precios. Ejecutar casos de permisos y vigencias. | D11: Resolver precios y acuerdos en Python. API de edición/publicación que invoca contratos autorizados. Casos de cambio concurrente y precio inválido. | E11: Tarifa vigente publicada se obtiene del servidor. Borrador no cotizable. Separación de rol precios/disponibilidad. UI y motor muestran la misma versión. | F11: Orden interno: esquema/contrato; luego API y pantalla en paralelo; por último integración y pruebas. | G11: BE-008, BE-009, BE-010, FE-015 | H11: =COUNTIFS('Asignación 83'!$F$7:$F$89,A11)
A12: 5 | B12: Cotizar, reservar y conciliar | C12: RPC transaccionales de ocupación, instantáneas y restricciones. Conectar calendario, cotización multivalla, impresión y reapertura. Validar dos sesiones reales. | D12: Cálculo, guardado/emisión, ciclo comercial y permisos de descuento. Expiración y conciliación Odoo. Migrar piloto con el contrato de importación que tú ejecutas. | E12: Crear, emitir, consultar, reservar, reprogramar y cancelar. Sin doble reserva ni duplicado ERP. Cambio de tarifa controlado. Documento imprimible coincide. Migración conciliada. | F12: Es una entrega conjunta: calendario y cotización se necesitan. No cerrar una mitad dejando Odoo, soporte, concurrencia o emisión para después. | G12: BE-007, BE-011, BE-012, BE-013, BE-014, BE-015, BE-016, BE-019, INT-006, INT-016, SER-003, SER-012, FE-013, FE-014, FE-016 | H12: =COUNTIFS('Asignación 83'!$F$7:$F$89,A12)
A13: 6 | B13: Fabricación y renders | C13: Esquema configurable y solicitudes/resultados privados. Formularios por familia y seguimiento/revisión de renders con versiones. | D13: Motor de reglas de fabricación y proveedor de renders. Trabajos, límites, cancelación y errores. Mantener aprobación visual separada de contratación. | E13: Cotización configurable reproducible. Render ligado a versión, visible solo al cliente autorizado. Revisión no cambia precios ni reserva inventario. | F13: Proveedor, modalidad y reglas aprobados antes de desarrollar. Los trabajos reutilizan infraestructura de etapa 2. | G13: BE-018, BE-020, INT-011, FE-017, FE-018 | H13: =COUNTIFS('Asignación 83'!$F$7:$F$89,A13)
A14: 7 | B14: Captación y CRM | C14: Tablas/políticas de solicitudes y consentimiento. Formulario conectado al backend y respaldo WhatsApp. Validar recepción frente a alta CRM. | D14: Recepción y validación de interesados, adaptador CRM, reintentos y conciliación de resultados inciertos. | E14: Solicitud llega al destino CRM acordado una sola vez. Caída de Odoo conserva pendiente. No modifica contactos por solo coincidir el correo. | F14: Cerrar formulario, API y CRM en la misma etapa; un mensaje preparado en WhatsApp no se marca como lead registrado. | G14: BE-028, INT-007, INT-014, FE-006 | H14: =COUNTIFS('Asignación 83'!$F$7:$F$89,A14)
A15: 8 | B15: Pagos y reportes | C15: Esquema/RLS para pagos y reportes, archivos privados. Checkout, seguimiento y tableros/exportaciones propios. Validación por empresa. | D15: Pasarela, eventos verificados, conciliación y consultas/reportes. Exportaciones asíncronas. Probar duplicados y eventos fuera de orden. | E15: Pago verificado y conciliado según contrato. Exportación conserva alcance. Otro cliente no consulta ni descarga. Fallo ERP no borra pago confirmado. | F15: Primero contratos. Anderson prepara APIs y fixtures mientras tú haces esquema. Una sola operación activa por persona; pagos y reportes se atienden en orden dentro del paquete. | G15: BE-021, BE-022, INT-008, SER-004, FE-019, FE-020 | H15: =COUNTIFS('Asignación 83'!$F$7:$F$89,A15)
A16: 9 | B16: Contenido, sitio y redes | C16: Esquema editorial/RLS, CMS, blog, calendario de aprobación y páginas públicas. Casos reales, avisos legales y caché/SEO de contenido. | D16: Backend editorial, publicación versionada, adaptador de primera red y programación persistente. Confirmación, cancelación y métricas por canal. | E16: Editar, aprobar, publicar y retirar funciona. Cambiar contenido invalida aprobación. No duplica publicaciones. Sitio muestra contenido aprobado y no expone borradores. | F16: Proveedor y cuentas disponibles antes de entrar. Completar primera red acordada y todos los formatos del alcance aprobado. Ampliaciones solo mediante decisión registrada. | G16: BE-023, BE-024, BE-025, INT-009, FE-001, FE-007, FE-008, FE-009, FE-021, SER-013 | H16: =COUNTIFS('Asignación 83'!$F$7:$F$89,A16)
A17: 10 | B17: Circuito de pantallas | C17: Modelo de capacidad compartida en Supabase, restricciones y RLS. Consola de circuito, piezas, programación y estados. | D17: Reglas de capacidad en backend y adaptador del reproductor. Programación, desconexión, reintento, retiro y evidencia. | E17: Piloto real autorizado: capacidad no se sobrevende; pieza inválida falla; recepción no se confunde con reproducción; cancelación/offline verificadas. | F17: No depende de que el agente exista. Equipo/API, unidad vendida y acceso al piloto deben estar resueltos previamente. | G17: BE-017, BE-026, INT-010, FE-022 | H17: =COUNTIFS('Asignación 83'!$F$7:$F$89,A17)
A18: 11 | B18: Agente de respuesta | C18: Conversaciones/fuentes privadas en Supabase y políticas de acceso. Interfaz de chat bajo demanda y derivación humana. | D18: Proveedor de modelo y herramientas tipadas. Consultas autorizadas, límites, fuentes y defensa ante instrucciones maliciosas. Integrar CRM ya validado si entra al corte. | E18: Responde con fuentes vigentes; no revela datos ajenos ni inventa disponibilidad; deriva cuando no sabe. Inyección y acciones no autorizadas son rechazadas. | F18: Usar módulos terminados. No conceder capacidades de cobrar/reservar/publicar por el mero hecho de conectar el modelo. | G18: BE-027, INT-012, SER-008, FE-023 | H18: =COUNTIFS('Asignación 83'!$F$7:$F$89,A18)
A19: 12 | B19: Cierre integral y producción | C19: Auditoría frontend, accesibilidad/SEO y recorrido completo. Verificar Supabase, restauración y evidencia de los 83 requisitos. Completar acuerdos y aceptación. | D19: Pruebas de carga y fallo externo, alertas, recuperación API/trabajadores, secretos y despliegue. Corregir todos los fallos bloqueantes. | E19: 83 requisitos con evidencia y revisión aprobada; 20 decisiones acordadas; cero bloqueantes. Restauración probada y controles transversales verificados. Producción autorizada explícitamente. | F19: La seguridad, pruebas y observabilidad se aplican desde etapa 1. Esta etapa consolida resultados y verifica el sistema completo, no los introduce por primera vez. | G19: FE-024, FE-025, SER-006, SER-007, SER-009, SER-010, SER-011, SER-014 | H19: =COUNTIFS('Asignación 83'!$F$7:$F$89,A19)
A23: Regla | B23: Aplicación
A24: Comenzar ahora | B24: Tú verificas Supabase remoto y preparas el contrato de identidad. Anderson verifica FastAPI/Odoo y prueba la API existente. Solo lectura durante el diagnóstico; implementación después de acordar contratos.
A25: Límite de trabajo | B25: Máximo dos operaciones activas: una por persona. Dentro del paquete de etapa, atender un requisito a la vez por persona. Bloqueado y en revisión siguen contando como trabajo abierto.
A26: Regla de avance | B26: No comenzar la siguiente etapa hasta cerrar todos los requisitos asignados al corte, acordar decisiones de entrada y superar aceptación conjunta. Ningún fallo se oculta cambiando el estado a cerrado.
A27: Responsable y colaboración | B27: Un responsable de cierre por requisito evita duplicaciones. No significa que haga todas sus capas. Todo cambio Supabase lo ejecutas tú; Anderson nunca lo asume por ser dueño del backend.
A28: Orden dentro de cada etapa | B28: 1. Decisión y contrato. 2. Tú defines/aplicas esquema/RPC; Anderson implementa adaptadores contra ese contrato. 3. Tú conectas UI; Anderson hace pruebas backend, fallos y ajustes. 4. Prueba integrada y revisión cruzada.
A29: Si uno termina primero | B29: Ayuda a probar, revisar, documentar o resolver el bloqueo de la otra operación de la misma etapa. No abrir otro módulo ni dejar una funcionalidad a medias.
A30: Control de carga | B30: Tu frente reúne BD y UI. Anderson prepara OpenAPI, ejemplos, datos de prueba, validadores, scripts sin ejecución Supabase y automatización backend. Así aprovecha tu tiempo de migración y conexión de pantallas.
A31: Cambios de base de datos | B31: Un solo autor/ejecutor de migraciones Supabase: tú. Revisar compatibilidad antes de aplicar. Anderson solicita el cambio mediante contrato y casos; no introduce SQL alternativo.
A32: Contratos y entornos | B32: Usar la misma versión de OpenAPI, IDs, campos, errores y fixtures. Ramas/PR separados por operación. Mock sirve para desarrollar, nunca como evidencia de flujo terminado.
A33: Requisitos transversales | B33: La etapa 0 prepara decisiones y pruebas. SER-011 y SER-014 comienzan ejecución desde etapa 1, solo con sus prerrequisitos resueltos. Los controles transversales se verifican en cada entrega y cierran globalmente en etapa 12.
A34: Dependencias que forman pares | B34: La matriz original contiene relaciones recíprocas, por ejemplo backend y adaptador de pagos. Se resuelven como un paquete de contrato, implementación paralela e integración en una misma etapa, no como dos bloqueos circulares.
... A40: Fuente y corte | B40: Base: Hercas - Levantamiento de requerimientos.xlsx, hoja Requerimientos, IDs BE/FE/INT/SER, y Decisiones D-001 a D-020. Estado original preservado; este plan no acredita implementación nueva.

Sheet Asignación 83
A2: Asignación completa — 83 requisitos, un responsable de cierre por ID
A4: Etapa 0: solo diagnóstico, decisiones y contratos. La ejecución inicia desde etapa 1, cuando sus prerrequisitos estén resueltos. Todo Supabase queda contigo.
A6: ID | B6: Área | C6: Requerimiento | D6: Responsable de cierre | E6: Etapa inicio de ejecución | F6: Etapa cierre | G6: Tu parte: Supabase / frontend | H6: Colaboración del otro frente | I6: Dependencias originales | J6: Aceptación del requisito | K6: Estado de ejecución | L6: Revisión del otro | M6: Evidencia / enlace | N6: Fecha cierre | O6: Bloqueo / pendiente | P6: Cierre verificable
A7: BE-001 | B7: Backend | C7: API modular común | D7: Anderson | E7: 1 | F7: 1 | G7: Si requiere tablas, migraciones, RLS, RPC, Auth, Storage, Realtime o configuración Supabase, tú lo implementas. Anderson entrega contrato y casos de prueba. | H7: Tú implementas Supabase necesario, conectas frontend y ejecutas aceptación. Anderson no modifica el proyecto Supabase. | I7: — | J7: Healthcheck no depende de Odoo. Errores externos no revelan cuerpos ni secretos. Módulos futuros no se anuncian como rutas activas. | K7: Por iniciar | L7: Pendiente | P7: =IF(AND(K7="Cerrado",L7="Aprobada",M7<>"",ISNUMBER(N7),O7=""),"Sí","No")
A8: BE-002 | B8: Backend | C8: Sesión y autorización | D8: Anderson | E8: 1 | F8: 1 | G8: Si requiere tablas, migraciones, RLS, RPC, Auth, Storage, Realtime o configuración Supabase, tú lo implementas. Anderson entrega contrato y casos de prueba. | H8: Tú implementas Supabase necesario, conectas frontend y ejecutas aceptación. Anderson no modifica el proyecto Supabase. | I8: INT-002 | J8: Token inválido devuelve 401. Perfil inactivo o rol no autorizado no opera. Un usuario sin rol comercial puede tener sesión sin acceder al cotizador. | K8: Por iniciar | L8: Pendiente | P8: =IF(AND(K8="Cerrado",L8="Aprobada",M8<>"",ISNUMBER(N8),O8=""),"Sí","No")
A9: BE-003 | B9: Backend | C9: Empresas cliente y aislamiento | D9: Tú | E9: 1 | F9: 1 | G9: Modelo de empresas/membresías y RLS. | H9: Anderson entrega/ajusta API, contratos y pruebas backend requeridas. Revisa con evidencias el trabajo cerrado. | I9: BE-002, INT-002 | J9: El alcance se obtiene en servidor. Cambiar un ID no revela otra empresa. Revocar membresía retira acceso. | K9: Por iniciar | L9: Pendiente | P9: =IF(AND(K9="Cerrado",L9="Aprobada",M9<>"",ISNUMBER(N9),O9=""),"Sí","No")
A10: BE-004 | B10: Backend | C10: Aceptación de invitaciones | D10: Anderson | E10: 1 | F10: 1 | G10: Si requiere tablas, migraciones, RLS, RPC, Auth, Storage, Realtime o configuración Supabase, tú lo implementas. Anderson entrega contrato y casos de prueba. | H10: Tú implementas Supabase necesario, conectas frontend y ejecutas aceptación. Anderson no modifica el proyecto Supabase. | I10: BE-002, INT-003 | J10: Invitación vencida o revocada falla. Repetir aceptación no duplica roles ni restaura permisos revocados. No permite convertir cliente en empleado. | K10: Por iniciar | L10: Pendiente | P10: =IF(AND(K10="Cerrado",L10="Aprobada",M10<>"",ISNUMBER(N10),O10=""),"Sí","No")
A11: BE-005 | B11: Backend | C11: Administración de accesos | D11: Tú | E11: 1 | F11: 1 | G11: Migración y RPC de administración de accesos. | H11: Anderson entrega/ajusta API, contratos y pruebas backend requeridas. Revisa con evidencias el trabajo cerrado. | I11: BE-002, BE-004 | J11: Solo users.manage opera. Rol inválido se rechaza. El último administrador permanece activo. Un envío de correo fallido no se reporta como invitación entregada. | K11: Por iniciar | L11: Pendiente | P11: =IF(AND(K11="Cerrado",L11="Aprobada",M11<>"",ISNUMBER(N11),O11=""),"Sí","No")
A12: BE-006 | B12: Backend | C12: Consultas de catálogo, activos y clientes | D12: Anderson | E12: 3 | F12: 3 | G12: Si requiere tablas, migraciones, RLS, RPC, Auth, Storage, Realtime o configuración Supabase, tú lo implementas. Anderson entrega contrato y casos de prueba. | H12: Tú implementas Supabase necesario, conectas frontend y ejecutas aceptación. Anderson no modifica el proyecto Supabase. | I12: BE-002, INT-004 | J12: Límite entre 1 y 100. Inventario no expone source_metadata ni soportes. Productos ocultos no se ofrecen. | K12: Por iniciar | L12: Pendiente | P12: =IF(AND(K12="Cerrado",L12="Aprobada",M12<>"",ISNUMBER(N12),O12=""),"Sí","No")
A13: BE-007 | B13: Backend | C13: Simulación aritmética | D13: Anderson | E13: 5 | F13: 5 | G13: Si requiere tablas, migraciones, RLS, RPC, Auth, Storage, Realtime o configuración Supabase, tú lo implementas. Anderson entrega contrato y casos de prueba. | H13: Tú implementas Supabase necesario, conectas frontend y ejecutas aceptación. Anderson no modifica el proyecto Supabase. | I13: BE-002 | J13: Caso documentado produce 4.926.600 COP. Rechaza valores no finitos y fuera de rango. El resultado no constituye documento oficial. | K13: Por iniciar | L13: Pendiente | P13: =IF(AND(K13="Cerrado",L13="Aprobada",M13<>"",ISNUMBER(N13),O13=""),"Sí","No")
A14: BE-008 | B14: Backend | C14: Resolución de precios y acuerdos | D14: Anderson | E14: 4 | F14: 4 | G14: Si requiere tablas, migraciones, RLS, RPC, Auth, Storage, Realtime o configuración Supabase, tú lo implementas. Anderson entrega contrato y casos de prueba. | H14: Tú implementas Supabase necesario, conectas frontend y ejecutas aceptación. Anderson no modifica el proyecto Supabase. | I14: BE-009, BE-010 | J14: Borradores no resuelven precio cotizable. Vigencia inclusiva. Publicación requiere autor y fecha. La revisión mensual no invalida por sí sola la última tarifa publicada. | K14: Por iniciar | L14: Pendiente | P14: =IF(AND(K14="Cerrado",L14="Aprobada",M14<>"",ISNUMBER(N14),O14=""),"Sí","No")
A15: BE-009 | B15: Backend | C15: Versiones oficiales de tarifas | D15: Tú | E15: 4 | F15: 4 | G15: Versiones, vigencias y restricciones de precios. | H15: Anderson entrega/ajusta API, contratos y pruebas backend requeridas. Revisa con evidencias el trabajo cerrado. | I15: BE-006, D-003 | J15: No se superponen versiones publicadas de un producto. Una versión publicada se retira, no cambia su importe. Disponibilidad no concede permiso de precios. | K15: Por iniciar | L15: Pendiente | P15: =IF(AND(K15="Cerrado",L15="Aprobada",M15<>"",ISNUMBER(N15),O15=""),"Sí","No")
A16: BE-010 | B16: Backend | C16: Gestión de tarifas por API | D16: Anderson | E16: 4 | F16: 4 | G16: Si requiere tablas, migraciones, RLS, RPC, Auth, Storage, Realtime o configuración Supabase, tú lo implementas. Anderson entrega contrato y casos de prueba. | H16: Tú implementas Supabase necesario, conectas frontend y ejecutas aceptación. Anderson no modifica el proyecto Supabase. | I16: BE-009, D-003 | J16: Un usuario sin permiso no publica. Dos ediciones incompatibles devuelven conflicto. Una publicación registra actor, fecha y versión. | K16: Por iniciar | L16: Pendiente | P16: =IF(AND(K16="Cerrado",L16="Aprobada",M16<>"",ISNUMBER(N16),O16=""),"Sí","No")
A17: BE-011 | B17: Backend | C17: Cotización persistida e instantáneas | D17: Tú | E17: 5 | F17: 5 | G17: Cabecera, líneas, instantáneas y restricciones SQL. | H17: Anderson entrega/ajusta API, contratos y pruebas backend requeridas. Revisa con evidencias el trabajo cerrado. | I17: BE-009 | J17: La BD resuelve el precio oficial. Emisión exige líneas y vigencia. Documento emitido no cambia con una tarifa nueva. No asumir equivalencia del redondeo SQL y piloto. | K17: Por iniciar | L17: Pendiente | P17: =IF(AND(K17="Cerrado",L17="Aprobada",M17<>"",ISNUMBER(N17),O17=""),"Sí","No")
A18: BE-012 | B18: Backend | C18: Guardado y emisión transaccional | D18: Anderson | E18: 5 | F18: 5 | G18: Si requiere tablas, migraciones, RLS, RPC, Auth, Storage, Realtime o configuración Supabase, tú lo implementas. Anderson entrega contrato y casos de prueba. | H18: Tú implementas Supabase necesario, conectas frontend y ejecutas aceptación. Anderson no modifica el proyecto Supabase. | I18: BE-010, BE-011, D-003, D-004 | J18: Fallo en una línea revierte el conjunto. Reenvío no duplica documento. Cambio de precio antes de confirmar exige revisión. Importes del cliente no gobiernan el guardado. | K18: Por iniciar | L18: Pendiente | P18: =IF(AND(K18="Cerrado",L18="Aprobada",M18<>"",ISNUMBER(N18),O18=""),"Sí","No")
... A20: BE-014 | B20: Backend | C20: Calendario de disponibilidad | D20: Anderson | E20: 5 | F20: 5 | G20: Si requiere tablas, migraciones, RLS, RPC, Auth, Storage, Realtime o configuración Supabase, tú lo implementas. Anderson entrega contrato y casos de prueba. | H20: Tú implementas Supabase necesario, conectas frontend y ejecutas aceptación. Anderson no modifica el proyecto Supabase. | I20: BE-006, BE-015 | J20: Valida orden y límite temporal del endpoint. Excluye separaciones vencidas y omite razones/soportes. Verifica estado operativo al reservar. | K20: Por iniciar | L20: Pendiente | P20: =IF(AND(K20="Cerrado",L20="Aprobada",M20<>"",ISNUMBER(N20),O20=""),"Sí","No")
A21: BE-015 | B21: Backend | C21: Alta y cancelación de ocupaciones | D21: Tú | E21: 5 | F21: 5 | G21: RPC de ocupación/cancelación, bloqueos y exclusión temporal. | H21: Anderson entrega/ajusta API, contratos y pruebas backend requeridas. Revisa con evidencias el trabajo cerrado. | I21: BE-003, D-005 | J21: Solo activo verificado, no provisional y exclusive_daily. No permite cruces activos. Cancelación exige motivo y revisión esperada. Reserva requiere soporte. | K21: En curso | L21: Pendiente | M21: 30/09: migracion harden_sales_hold aplicada en hercas-platform-dev. Prueba remota reversible: cotizacion ajena y fechas invalidas rechazadas; cotizacion propia aceptada; solapamiento rechazado. Sin datos de prueba persistidos. | N21: 46295 | O21: Pendiente: consulta unica y tablero de tres estados (disponible, reservada, ocupada), conexion a cotizador y website, vencimiento, pago, liberacion y conciliacion ERP; soportes privados en Storage y aceptacion integral. Ver docs/disponibilidad-centro-control.md. | P21: =IF(AND(K21="Cerrado",L21="Aprobada",M21<>"",ISNUMBER(N21),O21=""),"Sí","No")
A22: BE-016 | B22: Backend | C22: Conversión y reprogramación de reserva | D22: Anderson | E22: 5 | F22: 5 | G22: Si requiere tablas, migraciones, RLS, RPC, Auth, Storage, Realtime o configuración Supabase, tú lo implementas. Anderson entrega contrato y casos de prueba. | H22: Tú implementas Supabase necesario, conectas frontend y ejecutas aceptación. Anderson no modifica el proyecto Supabase. | I22: BE-015, D-004, D-005 | J22: Conversión no libera temporalmente el activo. Dos sesiones no reservan el mismo intervalo. Reprogramación fallida conserva el periodo previo. | K22: Por iniciar | L22: Pendiente | P22: =IF(AND(K22="Cerrado",L22="Aprobada",M22<>"",ISNUMBER(N22),O22=""),"Sí","No")
A23: BE-017 | B23: Backend | C23: Disponibilidad compartida en pantallas | D23: Anderson | E23: 10 | F23: 10 | G23: Si requiere tablas, migraciones, RLS, RPC, Auth, Storage, Realtime o configuración Supabase, tú lo implementas. Anderson entrega contrato y casos de prueba. | H23: Tú implementas Supabase necesario, conectas frontend y ejecutas aceptación. Anderson no modifica el proyecto Supabase. | I23: D-006, BE-015 | J23: La suma de capacidad confirmada no excede el cupo. Modelo diario exclusivo no se aplica por defecto a venta parcial. | K23: Por iniciar | L23: Pendiente | P23: =IF(AND(K23="Cerrado",L23="Aprobada",M23<>"",ISNUMBER(N23),O23=""),"Sí","No")
A24: BE-018 | B24: Backend | C24: Productos configurables y reglas técnicas | D24: Anderson | E24: 6 | F24: 6 | G24: Si requiere tablas, migraciones, RLS, RPC, Auth, Storage, Realtime o configuración Supabase, tú lo implementas. Anderson entrega contrato y casos de prueba. | H24: Tú implementas Supabase necesario, conectas frontend y ejecutas aceptación. Anderson no modifica el proyecto Supabase. | I24: INT-004, D-003, D-007 | J24: Valida combinaciones permitidas. Conservar regla y parámetros usados. 7.488 filas de atributos no se convierten automáticamente en SKU. Costos no son tarifas de venta. | K24: Por iniciar | L24: Pendiente | P24: =IF(AND(K24="Cerrado",L24="Aprobada",M24<>"",ISNUMBER(N24),O24=""),"Sí","No")
A25: BE-019 | B25: Backend | C25: Aprobaciones, descuentos y ciclo comercial | D25: Anderson | E25: 5 | F25: 5 | G25: Si requiere tablas, migraciones, RLS, RPC, Auth, Storage, Realtime o configuración Supabase, tú lo implementas. Anderson entrega contrato y casos de prueba. | H25: Tú implementas Supabase necesario, conectas frontend y ejecutas aceptación. Anderson no modifica el proyecto Supabase. | I25: D-003, D-004 | J25: Solo rol autorizado aprueba descuento. Corregir emitida crea nueva versión. Aceptación comercial no reserva ni cobra sin regla acordada. | K25: Por iniciar | L25: Pendiente | P25: =IF(AND(K25="Cerrado",L25="Aprobada",M25<>"",ISNUMBER(N25),O25=""),"Sí","No")
A26: BE-020 | B26: Backend | C26: Solicitud y versiones de render | D26: Anderson | E26: 6 | F26: 6 | G26: Si requiere tablas, migraciones, RLS, RPC, Auth, Storage, Realtime o configuración Supabase, tú lo implementas. Anderson entrega contrato y casos de prueba. | H26: Tú implementas Supabase necesario, conectas frontend y ejecutas aceptación. Anderson no modifica el proyecto Supabase. | I26: D-008, SER-005 | J26: Solicitud persiste sin generación inmediata. Resultados versionados y privados. Aprobación visual no modifica precio ni reserva inventario. | K26: Por iniciar | L26: Pendiente | P26: =IF(AND(K26="Cerrado",L26="Aprobada",M26<>"",ISNUMBER(N26),O26=""),"Sí","No")
A27: BE-021 | B27: Backend | C27: Consultas internas y por cliente | D27: Anderson | E27: 8 | F27: 8 | G27: Si requiere tablas, migraciones, RLS, RPC, Auth, Storage, Realtime o configuración Supabase, tú lo implementas. Anderson entrega contrato y casos de prueba. | H27: Tú implementas Supabase necesario, conectas frontend y ejecutas aceptación. Anderson no modifica el proyecto Supabase. | I27: BE-003, INT-005, D-009 | J27: Filtrar empresa antes de agregar. Mostrar fecha de datos. Otra empresa no accede cambiando parámetros. Definir cada indicador y fuente. | K27: Por iniciar | L27: Pendiente | P27: =IF(AND(K27="Cerrado",L27="Aprobada",M27<>"",ISNUMBER(N27),O27=""),"Sí","No")
A28: BE-022 | B28: Backend | C28: Intenciones y estados de pago | D28: Anderson | E28: 8 | F28: 8 | G28: Si requiere tablas, migraciones, RLS, RPC, Auth, Storage, Realtime o configuración Supabase, tú lo implementas. Anderson entrega contrato y casos de prueba. | H28: Tú implementas Supabase necesario, conectas frontend y ejecutas aceptación. Anderson no modifica el proyecto Supabase. | I28: BE-012, INT-008, D-010 | J28: Total se obtiene del servidor. Página de retorno no confirma pago. Separar pago confirmado de conciliación ERP pendiente. | K28: Por iniciar | L28: Pendiente | P28: =IF(AND(K28="Cerrado",L28="Aprobada",M28<>"",ISNUMBER(N28),O28=""),"Sí","No")
A29: BE-023 | B29: Backend | C29: Edición y publicación de páginas | D29: Anderson | E29: 9 | F29: 9 | G29: Si requiere tablas, migraciones, RLS, RPC, Auth, Storage, Realtime o configuración Supabase, tú lo implementas. Anderson entrega contrato y casos de prueba. | H29: Tú implementas Supabase necesario, conectas frontend y ejecutas aceptación. Anderson no modifica el proyecto Supabase. | I29: BE-002, SER-005, D-011 | J29: Público solo ve publicado. Borrador/preview requieren permiso. Publicación identifica versión y actor, y actualiza caché. | K29: Por iniciar | L29: Pendiente | P29: =IF(AND(K29="Cerrado",L29="Aprobada",M29<>"",ISNUMBER(N29),O29=""),"Sí","No")
A30: BE-024 | B30: Backend | C30: Artículos y calendario editorial | D30: Anderson | E30: 9 | F30: 9 | G30: Si requiere tablas, migraciones, RLS, RPC, Auth, Storage, Realtime o configuración Supabase, tú lo implementas. Anderson entrega contrato y casos de prueba. | H30: Tú implementas Supabase necesario, conectas frontend y ejecutas aceptación. Anderson no modifica el proyecto Supabase. | I30: BE-023, D-012 | J30: Campaña puede existir sin artículo. Variantes conservan cuenta, recursos y versión. No inventar promociones o precios. | K30: Por iniciar | L30: Pendiente | P30: =IF(AND(K30="Cerrado",L30="Aprobada",M30<>"",ISNUMBER(N30),O30=""),"Sí","No")
A31: BE-025 | B31: Backend | C31: Aprobación y publicación social | D31: Anderson | E31: 9 | F31: 9 | G31: Si requiere tablas, migraciones, RLS, RPC, Auth, Storage, Realtime o configuración Supabase, tú lo implementas. Anderson entrega contrato y casos de prueba. | H31: Tú implementas Supabase necesario, conectas frontend y ejecutas aceptación. Anderson no modifica el proyecto Supabase. | I31: BE-024, INT-009, SER-002 | J31: Modificar contenido o destino invalida aprobación. Fallo de una red no republica en otras. Resultado ambiguo se reconcilia antes de repetir. | K31: Por iniciar | L31: Pendiente | P31: =IF(AND(K31="Cerrado",L31="Aprobada",M31<>"",ISNUMBER(N31),O31=""),"Sí","No")
A32: BE-026 | B32: Backend | C32: Campañas y programación técnica | D32: Anderson | E32: 10 | F32: 10 | G32: Si requiere tablas, migraciones, RLS, RPC, Auth, Storage, Realtime o configuración Supabase, tú lo implementas. Anderson entrega contrato y casos de prueba. | H32: Tú implementas Supabase necesario, conectas frontend y ejecutas aceptación. Anderson no modifica el proyecto Supabase. | I32: BE-017, INT-010, D-006 | J32: Solo programa capacidad autorizada. Valida formato, duración y orientación. Registrar distribución y reproducción como hechos distintos. | K32: Por iniciar | L32: Pendiente | P32: =IF(AND(K32="Cerrado",L32="Aprobada",M32<>"",ISNUMBER(N32),O32=""),"Sí","No")
A33: BE-027 | B33: Backend | C33: Consulta con fuentes y derivación | D33: Anderson | E33: 11 | F33: 11 | G33: Si requiere tablas, migraciones, RLS, RPC, Auth, Storage, Realtime o configuración Supabase, tú lo implementas. Anderson entrega contrato y casos de prueba. | H33: Tú implementas Supabase necesario, conectas frontend y ejecutas aceptación. Anderson no modifica el proyecto Supabase. | I33: INT-012, SER-008, D-013 | J33: Fuentes privadas filtradas antes de recuperación. No inventa precio/disponibilidad. No tiene SQL libre ni credenciales Odoo generales. | K33: Por iniciar | L33: Pendiente | P33: =IF(AND(K33="Cerrado",L33="Aprobada",M33<>"",ISNUMBER(N33),O33=""),"Sí","No")
